Workbook
Name Slicer_Sales_Rep: #N/A
Name Slicer_Years__Date1: #N/A

Sheet Pharmacy_Analysis_Clean
A1: Date | B1: Region ID | C1: Region | D1: DRUG ID | E1: Drug Name | F1: Category ID | G1: Category | H1: SALES REP ID | I1: Sales Rep | J1: Units Sold | K1: Unit Price | L1: Revenue | M1: Cost | N1: Profit | O1: Year | P1: R.Year | Q1: Total_Revenue | R1: p.Year | S1: Profit2 | T1: q.Year | U1: Qty. Sold
A2: 45305 | B2: WN/101 | C2: Western Nigeria | D2: DIA | E2: Diafast | F2: CAT-DIAB | G2: Diabetes Care | H2: REP/001 | I2: Mohammed Bello | J2: 169 | K2: 37 | L2: 6253 | M2: 6109 | N2: 144 | O2: =YEAR(A2) -> 2024 | P2: 2024 | Q2: 2520760 | R2: 2024 | S2: 191255 | T2: 2024 | U2: 39486
A3: 45306 | B3: NN/101 | C3: Northern Nigeria | D3: CAR | E3: CardioVex | F3: CAT-CARD | G3: Cardiovascular | H3: REP/002 | I3: Grace Umeh | J3: 185 | K3: 52 | L3: 9620 | M3: 9344 | N3: 276 | O3: =YEAR(A3) -> 2024 | P3: 2025 | Q3: 1093005 | R3: 2025 | S3: 81617 | T3: 2025 | U3: 16501
A4: 45307 | B4: EN/101 | C4: Eastern Nigeria | D4: HEA | E4: Heartzol | F4: CAT-CARD | G4: Cardiovascular | H4: REP/003 | I4: Jane Akins | J4: 126 | K4: 56 | L4: 7056 | M4: 6940 | N4: 116 | O4: =YEAR(A4) -> 2024
A5: 45308 | B5: EN/101 | C5: Eastern Nigeria | D5: HEA | E5: Heartzol | F5: CAT-CARD | G5: Cardiovascular | H5: REP/003 | I5: Jane Akins | J5: 78 | K5: 70 | L5: 5460 | M5: 5270 | N5: 190 | O5: =YEAR(A5) -> 2024
A6: 45309 | B6: WN/101 | C6: Western Nigeria | D6: MAX | E6: Maxilin | F6: CAT-ANBX | G6: Antibiotic | H6: REP/004 | I6: Laila Hussein | J6: 147 | K6: 62 | L6: 9114 | M6: 8484 | N6: 630 | O6: =YEAR(A6) -> 2024
A7: 45310 | B7: NN/101 | C7: Northern Nigeria | D7: MAX | E7: Maxilin | F7: CAT-ANBX | G7: Antibiotic | H7: REP/003 | I7: Jane Akins | J7: 184 | K7: 63 | L7: 11592 | M7: 10681 | N7: 911 | O7: =YEAR(A7) -> 2024
A8: 45311 | B8: EN/101 | C8: Eastern Nigeria | D8: MAX | E8: Maxilin | F8: CAT-ANBX | G8: Antibiotic | H8: REP/004 | I8: Laila Hussein | J8: 75 | K8: 39 | L8: 2925 | M8: 2596 | N8: 329 | O8: =YEAR(A8) -> 2024
A9: 45312 | B9: NN/101 | C9: Northern Nigeria | D9: MAX | E9: Maxilin | F9: CAT-ANBX | G9: Antibiotic | H9: REP/004 | I9: Laila Hussein | J9: 125 | K9: 80 | L9: 10000 | M9: 9442 | N9: 558 | O9: =YEAR(A9) -> 2024
A10: 45313 | B10: SN/101 | C10: Southern Nigeria | D10: DIA | E10: Diafast | F10: CAT-DIAB | G10: Diabetes Care | H10: REP/003 | I10: Jane Akins | J10: 169 | K10: 71 | L10: 11999 | M10: 11132 | N10: 867 | O10: =YEAR(A10) -> 2024
A11: 45314 | B11: WN/101 | C11: Western Nigeria | D11: DIA | E11: Diafast | F11: CAT-DIAB | G11: Diabetes Care | H11: REP/005 | I11: Emeka Obi | J11: 68 | K11: 80 | L11: 5440 | M11: 5121 | N11: 319 | O11: =YEAR(A11) -> 2024
A12: 45315 | B12: SN/101 | C12: Southern Nigeria | D12: MAX | E12: Maxilin | F12: CAT-ANBX | G12: Antibiotic | H12: REP/002 | I12: Grace Umeh | J12: 83 | K12: 43 | L12: 3569 | M12: 2927 | N12: 642 | O12: =YEAR(A12) -> 2024
A13: 45316 | B13: WN/101 | C13: Western Nigeria | D13: NEU | E13: Neuroflex | F13: CAT-PAIN | G13: Pain Relief | H13: REP/003 | I13: Jane Akins | J13: 126 | K13: 86 | L13: 10836 | M13: 9967 | N13: 869 | O13: =YEAR(A13) -> 2024
A14: 45317 | B14: SN/101 | C14: Southern Nigeria | D14: HEA | E14: Heartzol | F14: CAT-CARD | G14: Cardiovascular | H14: REP/001 | I14: Mohammed Bello | J14: 186 | K14: 47 | L14: 8742 | M14: 8216 | N14: 526 | O14: =YEAR(A14) -> 2024
A15: 45318 | B15: SN/101 | C15: Southern Nigeria | D15: REL | E15: Relipain | F15: CAT-PAIN | G15: Pain Relief | H15: REP/005 | I15: Emeka Obi | J15: 57 | K15: 84 | L15: 4788 | M15: 3804 | N15: 984 | O15: =YEAR(A15) -> 2024
... A503: 45806 | B503: NN/101 | C503: Northern Nigeria | D503: MAX | E503: Maxilin | F503: CAT-ANBX | G503: Antibiotic | H503: REP/004 | I503: Laila Hussein | J503: 125 | K503: 80 | L503: 10000 | M503: 9442 | N503: 558 | O503: =YEAR(A503) -> 2025
J504: =SUM(J2:J503) -> 55987 | K504: =AVERAGE(K2:K503) -> 65.055777 | L504: =_xlfn.AGGREGATE(9,4,L2:L503) -> 3613765 | N504: =SUM(N2:N503) -> 272872

Sheet Pivot
A2: Revenue Trend
A3: Row Labels | B3: Monthly Revenue | D3: Drug Category by Revenue | G3: Revenue & Unit Sold by Rep_ID | K3: Drug Brand Performance
A4: Jan | B4: 344620 | D4: Row Labels | E4: Category Revenue | G4: Sales Rep ID | H4: Rep.Revenue | I4: Rep.Quantity Sold | K4: Drug Name | L4: Quantity_Sold | M4: Total_Profit | N4: Total_Revenue
A5: Feb | B5: 427535 | D5: Cardiovascular | E5: 1008080 | G5: REP/001 | H5: 882447 | I5: 13712 | K5: CardioVex | L5: 7076 | M5: 31855 | N5: 455841
A6: Mar | B6: 436806 | D6: Antibiotic | E6: 913319 | G6: REP/002 | H6: 757817 | I6: 11683 | K6: Diafast | L6: 6419 | M6: 29117 | N6: 408883
A7: Apr | B7: 382127 | D7: Diabetes Care | E7: 896484 | G7: REP/003 | H7: 620995 | I7: 10230 | K7: Glucorin | L7: 7873 | M7: 37392 | N7: 487601
A8: May | B8: 514282 | D8: Pain Relief | E8: 795882 | G8: REP/004 | H8: 651908 | I8: 10462 | K8: Heartzol | L8: 8276 | M8: 40332 | N8: 552239
A9: Jun | B9: 209973 | G9: REP/005 | H9: 700598 | I9: 9900 | K9: Maxilin | L9: 8221 | M9: 41721 | N9: 501628
A10: Jul | B10: 203434 | D10: Revenue Distribution by Region | K10: Neuroflex | L10: 5039 | M10: 27115 | N10: 315670
A11: Aug | B11: 212044 | D11: Region | E11: Region Revenue | G11: Regional Quantity vs Profit Comparison | K11: Relipain | L11: 7046 | M11: 37751 | N11: 480212
A12: Sep | B12: 209534 | D12: Western Nigeria | E12: 989156 | G12: Region | H12: Quantity Sold | I12: Regional Profit | K12: Zymetra | L12: 6037 | M12: 27589 | N12: 411691
A13: Oct | B13: 228212 | D13: Southern Nigeria | E13: 945154 | G13: Western Nigeria | H13: 14904 | I13: 68664
A14: Nov | B14: 209176 | D14: Northern Nigeria | E14: 882348 | G14: Southern Nigeria | H14: 14450 | I14: 69294
A15: Dec | B15: 236022 | D15: Eastern Nigeria | E15: 797107 | G15: Northern Nigeria | H15: 14180 | I15: 72395 | K15: =K4 -> Drug Name | L15: =L4 -> Quantity_Sold | M15: =M4 -> Total_Profit | N15: =N4 -> Total_Revenue
G16: Eastern Nigeria | H16: 12453 | I16: 62519 | K16: =K5 -> CardioVex | L16: =L5 -> 7076 | M16: =M5 -> 31855 | N16: =N5 -> 455841
K17: =K6 -> Diafast | L17: =L6 -> 6419 | M17: =M6 -> 29117 | N17: =N6 -> 408883
A18: Seasonal Drug Demand Pattern | K18: =K7 -> Glucorin | L18: =L7 -> 7873 | M18: =M7 -> 37392 | N18: =N7 -> 487601
A19: Sum of Units Sold | B19: Column Labels | G19: =G12 -> Region | H19: =H12 -> Quantity Sold | I19: =I12 -> Regional Profit | K19: =K8 -> Heartzol | L19: =L8 -> 8276 | M19: =M8 -> 40332 | N19: =N8 -> 552239
A20: Months | B20: Antibiotic | C20: Cardiovascular | D20: Diabetes Care | E20: Pain Relief | G20: =G13 -> Western Nigeria | H20: =H13 -> 14904 | I20: =I13 -> 68664 | K20: =K9 -> Maxilin | L20: =L9 -> 8221 | M20: =M9 -> 41721 | N20: =N9 -> 501628
A21: Jan | B21: 2006 | C21: 921 | D21: 1295 | E21: 1365 | G21: =G14 -> Southern Nigeria | H21: =H14 -> 14450 | I21: =I14 -> 69294 | K21: =K10 -> Neuroflex | L21: =L10 -> 5039 | M21: =M10 -> 27115 | N21: =N10 -> 315670
A22: Feb | B22: 1709 | C22: 1764 | D22: 1542 | E22: 1371 | G22: =G15 -> Northern Nigeria | H22: =H15 -> 14180 | I22: =I15 -> 72395 | K22: =K11 -> Relipain | L22: =L11 -> 7046 | M22: =M11 -> 37751 | N22: =N11 -> 480212
A23: Mar | B23: 1248 | C23: 1165 | D23: 1938 | E23: 2206 | G23: =G16 -> Eastern Nigeria | H23: =H16 -> 12453 | I23: =I16 -> 62519 | K23: =K12 -> Zymetra | L23: =L12 -> 6037 | M23: =M12 -> 27589 | N23: =N12 -> 411691
A24: Apr | B24: 2038 | C24: 1773 | D24: 1613 | E24: 805
A25: May | B25: 2030 | C25: 2178 | D25: 1815 | E25: 1583 | G25: Regional Health Trend
A26: Jun | B26: 381 | C26: 1042 | D26: 959 | E26: 813 | G26: Sum of Uni
A27: Jul | B27: 493 | C27: 1344 | D27: 778 | E27: 678 | G27: Category | H27: Western Nigeria | I27: Southern Nigeria | J27: Northern Nigeria | K27: Eastern Nigeria | M27: Region | N27: Region Revenue
A28: Aug | B28: 925 | C28: 918 | D28: 1076 | E28: 521 | G28: Pain Relief | H28: 2924 | I28: 4128 | J28: 2746 | K28: 2287 | M28: 2024 | N28: 2520760
A29: Sep | B29: 998 | C29: 1115 | D29: 932 | E29: 491 | G29: Diabetes Care | H29: 3873 | I29: 3412 | J29: 3699 | K29: 3308 | M29: 2025 | N29: 1093005
A30: Oct | B30: 864 | C30: 688 | D30: 1117 | E30: 790 | G30: Cardiovascular | H30: 4321 | I30: 3978 | J30: 3690 | K30: 3363
A31: Nov | B31: 811 | C31: 1184 | D31: 910 | E31: 350 | G31: Antibiotic | H31: 3786 | I31: 2932 | J31: 4045 | K31: 3495
A32: Dec | B32: 755 | C32: 1260 | D32: 317 | E32: 1112
D34: =G34 -> Total Revenue | E34: =H34 -> Total Revenue | G34: Total Revenue | H34: =G34 -> Total Revenue | J34: Year | K34: Total Revenue | L34: =J34 -> Year | M34: =K34 -> Total Revenue
D35: =G35 -> 3613765 | E35: =IFERROR(GETPIVOTDATA("Revenue",$G$34,"Years (Date)",2024),2520760) -> 2520760 | G35: 3613765 | H35: =GETPIVOTDATA("Revenue",$G$34) -> 3613765 | J35: 2024 | K35: 2520760 | L35: =J35 -> 2024 | M35: =K35 -> 2520760
D36: =G36 -> 0 | E36: =IFERROR(GETPIVOTDATA("Revenue",$G$34,"Years (Date)",2025),1093005) -> 1093005 | J36: 2025 | K36: 1093005 | L36: =J36 -> 2025 | M36: =K36 -> 1093005
E37: =IF(E35=0," ",(E36-E35)/E35) -> -0.56639863 | M37: =(M36-M35)/M35 -> -0.56639863
A38: Region | B38: Region Revenue | M38: =IF(M37="","0%",TEXT(M37,"+0.0%;-0.0%")&IF(M37>0,"↑",IF(M37<0,"↓",""))) -> -56.6%↓
A39: 2024 | B39: 2520760 | G39: Year | H39: Total Revenue | I39: Growth % | J39: QtySold | K39: =J39 -> QtySold
A40: 2025 | B40: 1093005 | G40: 2024 | H40: 2520760 | J40: 55987 | K40: =J40 -> 55987
G41: 2025 | H41: 1093005 | I41: -0.56639863
A43: Region | B43: Region Revenue | D43: Region | E43: Region Revenue | G43: Region | H43: S_rep Revenue | J43: Year | K43: QtySold | L43: =J43 -> Year | M43: =K43 -> QtySold
...

Sheet Dashboard1

Sheet Dashboard2
D11: =Pivot!A20 -> Months | E11: =Pivot!B20 -> Antibiotic | F11: =Pivot!C20 -> Cardiovascular | G11: =Pivot!D20 -> Diabetes Care | H11: =Pivot!E20 -> Pain Relief
D12: =Pivot!A21 -> Jan | E12: =Pivot!B21 -> 2006 | F12: =Pivot!C21 -> 921 | G12: =Pivot!D21 -> 1295 | H12: =Pivot!E21 -> 1365
D13: =Pivot!A22 -> Feb | E13: =Pivot!B22 -> 1709 | F13: =Pivot!C22 -> 1764 | G13: =Pivot!D22 -> 1542 | H13: =Pivot!E22 -> 1371
D14: =Pivot!A23 -> Mar | E14: =Pivot!B23 -> 1248 | F14: =Pivot!C23 -> 1165 | G14: =Pivot!D23 -> 1938 | H14: =Pivot!E23 -> 2206
D15: =Pivot!A24 -> Apr | E15: =Pivot!B24 -> 2038 | F15: =Pivot!C24 -> 1773 | G15: =Pivot!D24 -> 1613 | H15: =Pivot!E24 -> 805
D16: =Pivot!A25 -> May | E16: =Pivot!B25 -> 2030 | F16: =Pivot!C25 -> 2178 | G16: =Pivot!D25 -> 1815 | H16: =Pivot!E25 -> 1583
D17: =Pivot!A26 -> Jun | E17: =Pivot!B26 -> 381 | F17: =Pivot!C26 -> 1042 | G17: =Pivot!D26 -> 959 | H17: =Pivot!E26 -> 813
D18: =Pivot!A27 -> Jul | E18: =Pivot!B27 -> 493 | F18: =Pivot!C27 -> 1344 | G18: =Pivot!D27 -> 778 | H18: =Pivot!E27 -> 678
D19: =Pivot!A28 -> Aug | E19: =Pivot!B28 -> 925 | F19: =Pivot!C28 -> 918 | G19: =Pivot!D28 -> 1076 | H19: =Pivot!E28 -> 521
D20: =Pivot!A29 -> Sep | E20: =Pivot!B29 -> 998 | F20: =Pivot!C29 -> 1115 | G20: =Pivot!D29 -> 932 | H20: =Pivot!E29 -> 491
D21: =Pivot!A30 -> Oct | E21: =Pivot!B30 -> 864 | F21: =Pivot!C30 -> 688 | G21: =Pivot!D30 -> 1117 | H21: =Pivot!E30 -> 790
D22: =Pivot!A31 -> Nov | E22: =Pivot!B31 -> 811 | F22: =Pivot!C31 -> 1184 | G22: =Pivot!D31 -> 910 | H22: =Pivot!E31 -> 350
D23: =Pivot!A32 -> Dec | E23: =Pivot!B32 -> 755 | F23: =Pivot!C32 -> 1260 | G23: =Pivot!D32 -> 317 | H23: =Pivot!E32 -> 1112
D26: =Pivot!G27 -> Category | E26: =Pivot!H27 -> Western Nigeria | F26: =Pivot!I27 -> Southern Nigeria | G26: =Pivot!J27 -> Northern Nigeria | H26: =Pivot!K27 -> Eastern Nigeria
D27: =Pivot!G28 -> Pain Relief | E27: =Pivot!H28 -> 2924 | F27: =Pivot!I28 -> 4128 | G27: =Pivot!J28 -> 2746 | H27: =Pivot!K28 -> 2287
D28: =Pivot!G29 -> Diabetes Care | E28: =Pivot!H29 -> 3873 | F28: =Pivot!I29 -> 3412 | G28: =Pivot!J29 -> 3699 | H28: =Pivot!K29 -> 3308
D29: =Pivot!G30 -> Cardiovascular | E29: =Pivot!H30 -> 4321 | F29: =Pivot!I30 -> 3978 | G29: =Pivot!J30 -> 3690 | H29: =Pivot!K30 -> 3363
D30: =Pivot!G31 -> Antibiotic | E30: =Pivot!H31 -> 3786 | F30: =Pivot!I31 -> 2932 | G30: =Pivot!J31 -> 4045 | H30: =Pivot!K31 -> 3495
